20-07-01 00:22-ERROR- :: 302 != 0
Traceback (most recent call last):
  File "D:\PyCharm Community Edition 2020.1\plugins\python-ce\helpers\pycharm\teamcity\diff_tools.py", line 32, in _patched_equals
    old(self, first, second, msg)
  File "D:\python3.6.0\lib\unittest\case.py", line 821, in assertEqual
    assertion_func(first, second, msg=msg)
  File "D:\python3.6.0\lib\unittest\case.py", line 814, in _baseAssertEqual
    raise self.failureException(msg)
AssertionError: 302 != 0

During handling of the above exception, another exception occurred:

Traceback (most recent call last):
  File "C:\Users\legion\Desktop\API_AUTO\test_case\test_login.py", line 28, in test_api
    self.assertEqual(int(res.json()['ret']), item['expect'])
  File "D:\PyCharm Community Edition 2020.1\plugins\python-ce\helpers\pycharm\teamcity\diff_tools.py", line 38, in _patched_equals
    raise error
teamcity.diff_tools.EqualsAssertionError:  :: 302 != 0
20-07-01 00:22-ERROR- :: 302 != 0
Traceback (most recent call last):
  File "D:\PyCharm Community Edition 2020.1\plugins\python-ce\helpers\pycharm\teamcity\diff_tools.py", line 32, in _patched_equals
    old(self, first, second, msg)
  File "D:\python3.6.0\lib\unittest\case.py", line 821, in assertEqual
    assertion_func(first, second, msg=msg)
  File "D:\python3.6.0\lib\unittest\case.py", line 814, in _baseAssertEqual
    raise self.failureException(msg)
AssertionError: 302 != 0

During handling of the above exception, another exception occurred:

Traceback (most recent call last):
  File "C:\Users\legion\Desktop\API_AUTO\test_case\test_login.py", line 28, in test_api
    self.assertEqual(int(res.json()['ret']), item['expect'])
  File "D:\PyCharm Community Edition 2020.1\plugins\python-ce\helpers\pycharm\teamcity\diff_tools.py", line 38, in _patched_equals
    raise error
teamcity.diff_tools.EqualsAssertionError:  :: 302 != 0
20-07-01 00:22-ERROR- :: 302 != 0
Traceback (most recent call last):
  File "D:\PyCharm Community Edition 2020.1\plugins\python-ce\helpers\pycharm\teamcity\diff_tools.py", line 32, in _patched_equals
    old(self, first, second, msg)
  File "D:\python3.6.0\lib\unittest\case.py", line 821, in assertEqual
    assertion_func(first, second, msg=msg)
  File "D:\python3.6.0\lib\unittest\case.py", line 814, in _baseAssertEqual
    raise self.failureException(msg)
AssertionError: 302 != 0

During handling of the above exception, another exception occurred:

Traceback (most recent call last):
  File "C:\Users\legion\Desktop\API_AUTO\test_case\test_login.py", line 28, in test_api
    self.assertEqual(int(res.json()['ret']), item['expect'])
  File "D:\PyCharm Community Edition 2020.1\plugins\python-ce\helpers\pycharm\teamcity\diff_tools.py", line 38, in _patched_equals
    raise error
teamcity.diff_tools.EqualsAssertionError:  :: 302 != 0
20-07-01 00:31-ERROR- :: 302 != 0
Traceback (most recent call last):
  File "D:\PyCharm Community Edition 2020.1\plugins\python-ce\helpers\pycharm\teamcity\diff_tools.py", line 32, in _patched_equals
    old(self, first, second, msg)
  File "D:\python3.6.0\lib\unittest\case.py", line 821, in assertEqual
    assertion_func(first, second, msg=msg)
  File "D:\python3.6.0\lib\unittest\case.py", line 814, in _baseAssertEqual
    raise self.failureException(msg)
AssertionError: 302 != 0

During handling of the above exception, another exception occurred:

Traceback (most recent call last):
  File "C:\Users\legion\Desktop\API_AUTO\test_case\test_login.py", line 28, in test_api
    self.assertEqual(int(res.json()['ret']), item['expect'])
  File "D:\PyCharm Community Edition 2020.1\plugins\python-ce\helpers\pycharm\teamcity\diff_tools.py", line 38, in _patched_equals
    raise error
teamcity.diff_tools.EqualsAssertionError:  :: 302 != 0
20-07-01 00:31-ERROR- :: 302 != 0
Traceback (most recent call last):
  File "D:\PyCharm Community Edition 2020.1\plugins\python-ce\helpers\pycharm\teamcity\diff_tools.py", line 32, in _patched_equals
    old(self, first, second, msg)
  File "D:\python3.6.0\lib\unittest\case.py", line 821, in assertEqual
    assertion_func(first, second, msg=msg)
  File "D:\python3.6.0\lib\unittest\case.py", line 814, in _baseAssertEqual
    raise self.failureException(msg)
AssertionError: 302 != 0

During handling of the above exception, another exception occurred:

Traceback (most recent call last):
  File "C:\Users\legion\Desktop\API_AUTO\test_case\test_login.py", line 28, in test_api
    self.assertEqual(int(res.json()['ret']), item['expect'])
  File "D:\PyCharm Community Edition 2020.1\plugins\python-ce\helpers\pycharm\teamcity\diff_tools.py", line 38, in _patched_equals
    raise error
teamcity.diff_tools.EqualsAssertionError:  :: 302 != 0
20-07-01 00:31-ERROR- :: 302 != 0
Traceback (most recent call last):
  File "D:\PyCharm Community Edition 2020.1\plugins\python-ce\helpers\pycharm\teamcity\diff_tools.py", line 32, in _patched_equals
    old(self, first, second, msg)
  File "D:\python3.6.0\lib\unittest\case.py", line 821, in assertEqual
    assertion_func(first, second, msg=msg)
  File "D:\python3.6.0\lib\unittest\case.py", line 814, in _baseAssertEqual
    raise self.failureException(msg)
AssertionError: 302 != 0

During handling of the above exception, another exception occurred:

Traceback (most recent call last):
  File "C:\Users\legion\Desktop\API_AUTO\test_case\test_login.py", line 28, in test_api
    self.assertEqual(int(res.json()['ret']), item['expect'])
  File "D:\PyCharm Community Edition 2020.1\plugins\python-ce\helpers\pycharm\teamcity\diff_tools.py", line 38, in _patched_equals
    raise error
teamcity.diff_tools.EqualsAssertionError:  :: 302 != 0
20-07-01 00:31-ERROR- :: 302 != 0
Traceback (most recent call last):
  File "D:\PyCharm Community Edition 2020.1\plugins\python-ce\helpers\pycharm\teamcity\diff_tools.py", line 32, in _patched_equals
    old(self, first, second, msg)
  File "D:\python3.6.0\lib\unittest\case.py", line 821, in assertEqual
    assertion_func(first, second, msg=msg)
  File "D:\python3.6.0\lib\unittest\case.py", line 814, in _baseAssertEqual
    raise self.failureException(msg)
AssertionError: 302 != 0

During handling of the above exception, another exception occurred:

Traceback (most recent call last):
  File "C:\Users\legion\Desktop\API_AUTO\test_case\test_login.py", line 28, in test_api
    self.assertEqual(int(res.json()['ret']), item['expect'])
  File "D:\PyCharm Community Edition 2020.1\plugins\python-ce\helpers\pycharm\teamcity\diff_tools.py", line 38, in _patched_equals
    raise error
teamcity.diff_tools.EqualsAssertionError:  :: 302 != 0
20-07-01 00:31-ERROR- :: 302 != 0
Traceback (most recent call last):
  File "D:\PyCharm Community Edition 2020.1\plugins\python-ce\helpers\pycharm\teamcity\diff_tools.py", line 32, in _patched_equals
    old(self, first, second, msg)
  File "D:\python3.6.0\lib\unittest\case.py", line 821, in assertEqual
    assertion_func(first, second, msg=msg)
  File "D:\python3.6.0\lib\unittest\case.py", line 814, in _baseAssertEqual
    raise self.failureException(msg)
AssertionError: 302 != 0

During handling of the above exception, another exception occurred:

Traceback (most recent call last):
  File "C:\Users\legion\Desktop\API_AUTO\test_case\test_login.py", line 28, in test_api
    self.assertEqual(int(res.json()['ret']), item['expect'])
  File "D:\PyCharm Community Edition 2020.1\plugins\python-ce\helpers\pycharm\teamcity\diff_tools.py", line 38, in _patched_equals
    raise error
teamcity.diff_tools.EqualsAssertionError:  :: 302 != 0
20-07-01 00:31-ERROR- :: 302 != 0
Traceback (most recent call last):
  File "D:\PyCharm Community Edition 2020.1\plugins\python-ce\helpers\pycharm\teamcity\diff_tools.py", line 32, in _patched_equals
    old(self, first, second, msg)
  File "D:\python3.6.0\lib\unittest\case.py", line 821, in assertEqual
    assertion_func(first, second, msg=msg)
  File "D:\python3.6.0\lib\unittest\case.py", line 814, in _baseAssertEqual
    raise self.failureException(msg)
AssertionError: 302 != 0

During handling of the above exception, another exception occurred:

Traceback (most recent call last):
  File "C:\Users\legion\Desktop\API_AUTO\test_case\test_login.py", line 28, in test_api
    self.assertEqual(int(res.json()['ret']), item['expect'])
  File "D:\PyCharm Community Edition 2020.1\plugins\python-ce\helpers\pycharm\teamcity\diff_tools.py", line 38, in _patched_equals
    raise error
teamcity.diff_tools.EqualsAssertionError:  :: 302 != 0
20-07-01 00:32-ERROR- :: 1 != 0
Traceback (most recent call last):
  File "D:\PyCharm Community Edition 2020.1\plugins\python-ce\helpers\pycharm\teamcity\diff_tools.py", line 32, in _patched_equals
    old(self, first, second, msg)
  File "D:\python3.6.0\lib\unittest\case.py", line 821, in assertEqual
    assertion_func(first, second, msg=msg)
  File "D:\python3.6.0\lib\unittest\case.py", line 814, in _baseAssertEqual
    raise self.failureException(msg)
AssertionError: 1 != 0

During handling of the above exception, another exception occurred:

Traceback (most recent call last):
  File "C:\Users\legion\Desktop\API_AUTO\test_case\test_login.py", line 30, in test_api
    self.assertEqual(int(res.json()['ret']), item['expect'])
  File "D:\PyCharm Community Edition 2020.1\plugins\python-ce\helpers\pycharm\teamcity\diff_tools.py", line 38, in _patched_equals
    raise error
teamcity.diff_tools.EqualsAssertionError:  :: 1 != 0
20-07-01 00:32-ERROR- :: 1 != 0
Traceback (most recent call last):
  File "D:\PyCharm Community Edition 2020.1\plugins\python-ce\helpers\pycharm\teamcity\diff_tools.py", line 32, in _patched_equals
    old(self, first, second, msg)
  File "D:\python3.6.0\lib\unittest\case.py", line 821, in assertEqual
    assertion_func(first, second, msg=msg)
  File "D:\python3.6.0\lib\unittest\case.py", line 814, in _baseAssertEqual
    raise self.failureException(msg)
AssertionError: 1 != 0

During handling of the above exception, another exception occurred:

Traceback (most recent call last):
  File "C:\Users\legion\Desktop\API_AUTO\test_case\test_login.py", line 30, in test_api
    self.assertEqual(int(res.json()['ret']), item['expect'])
  File "D:\PyCharm Community Edition 2020.1\plugins\python-ce\helpers\pycharm\teamcity\diff_tools.py", line 38, in _patched_equals
    raise error
teamcity.diff_tools.EqualsAssertionError:  :: 1 != 0
20-07-01 00:32-ERROR- :: 1 != 0
Traceback (most recent call last):
  File "D:\PyCharm Community Edition 2020.1\plugins\python-ce\helpers\pycharm\teamcity\diff_tools.py", line 32, in _patched_equals
    old(self, first, second, msg)
  File "D:\python3.6.0\lib\unittest\case.py", line 821, in assertEqual
    assertion_func(first, second, msg=msg)
  File "D:\python3.6.0\lib\unittest\case.py", line 814, in _baseAssertEqual
    raise self.failureException(msg)
AssertionError: 1 != 0

During handling of the above exception, another exception occurred:

Traceback (most recent call last):
  File "C:\Users\legion\Desktop\API_AUTO\test_case\test_login.py", line 30, in test_api
    self.assertEqual(int(res.json()['ret']), item['expect'])
  File "D:\PyCharm Community Edition 2020.1\plugins\python-ce\helpers\pycharm\teamcity\diff_tools.py", line 38, in _patched_equals
    raise error
teamcity.diff_tools.EqualsAssertionError:  :: 1 != 0
20-07-01 00:33-ERROR- :: 1 != 0
Traceback (most recent call last):
  File "D:\PyCharm Community Edition 2020.1\plugins\python-ce\helpers\pycharm\teamcity\diff_tools.py", line 32, in _patched_equals
    old(self, first, second, msg)
  File "D:\python3.6.0\lib\unittest\case.py", line 821, in assertEqual
    assertion_func(first, second, msg=msg)
  File "D:\python3.6.0\lib\unittest\case.py", line 814, in _baseAssertEqual
    raise self.failureException(msg)
AssertionError: 1 != 0

During handling of the above exception, another exception occurred:

Traceback (most recent call last):
  File "C:\Users\legion\Desktop\API_AUTO\test_case\test_login.py", line 30, in test_api
    self.assertEqual(int(res.json()['ret']), item['expect'])
  File "D:\PyCharm Community Edition 2020.1\plugins\python-ce\helpers\pycharm\teamcity\diff_tools.py", line 38, in _patched_equals
    raise error
teamcity.diff_tools.EqualsAssertionError:  :: 1 != 0
20-07-01 00:33-ERROR- :: 1 != 0
Traceback (most recent call last):
  File "D:\PyCharm Community Edition 2020.1\plugins\python-ce\helpers\pycharm\teamcity\diff_tools.py", line 32, in _patched_equals
    old(self, first, second, msg)
  File "D:\python3.6.0\lib\unittest\case.py", line 821, in assertEqual
    assertion_func(first, second, msg=msg)
  File "D:\python3.6.0\lib\unittest\case.py", line 814, in _baseAssertEqual
    raise self.failureException(msg)
AssertionError: 1 != 0

During handling of the above exception, another exception occurred:

Traceback (most recent call last):
  File "C:\Users\legion\Desktop\API_AUTO\test_case\test_login.py", line 30, in test_api
    self.assertEqual(int(res.json()['ret']), item['expect'])
  File "D:\PyCharm Community Edition 2020.1\plugins\python-ce\helpers\pycharm\teamcity\diff_tools.py", line 38, in _patched_equals
    raise error
teamcity.diff_tools.EqualsAssertionError:  :: 1 != 0
20-07-01 00:46-ERROR- :: 1 != 0
Traceback (most recent call last):
  File "D:\PyCharm Community Edition 2020.1\plugins\python-ce\helpers\pycharm\teamcity\diff_tools.py", line 32, in _patched_equals
    old(self, first, second, msg)
  File "D:\python3.6.0\lib\unittest\case.py", line 821, in assertEqual
    assertion_func(first, second, msg=msg)
  File "D:\python3.6.0\lib\unittest\case.py", line 814, in _baseAssertEqual
    raise self.failureException(msg)
AssertionError: 1 != 0

During handling of the above exception, another exception occurred:

Traceback (most recent call last):
  File "C:\Users\legion\Desktop\API_AUTO\test_case\test_login.py", line 30, in test_api
    self.assertEqual(int(res.json()['ret']), item['expect'])
  File "D:\PyCharm Community Edition 2020.1\plugins\python-ce\helpers\pycharm\teamcity\diff_tools.py", line 38, in _patched_equals
    raise error
teamcity.diff_tools.EqualsAssertionError:  :: 1 != 0
20-07-01 00:46-ERROR- :: 1 != 0
Traceback (most recent call last):
  File "D:\PyCharm Community Edition 2020.1\plugins\python-ce\helpers\pycharm\teamcity\diff_tools.py", line 32, in _patched_equals
    old(self, first, second, msg)
  File "D:\python3.6.0\lib\unittest\case.py", line 821, in assertEqual
    assertion_func(first, second, msg=msg)
  File "D:\python3.6.0\lib\unittest\case.py", line 814, in _baseAssertEqual
    raise self.failureException(msg)
AssertionError: 1 != 0

During handling of the above exception, another exception occurred:

Traceback (most recent call last):
  File "C:\Users\legion\Desktop\API_AUTO\test_case\test_login.py", line 30, in test_api
    self.assertEqual(int(res.json()['ret']), item['expect'])
  File "D:\PyCharm Community Edition 2020.1\plugins\python-ce\helpers\pycharm\teamcity\diff_tools.py", line 38, in _patched_equals
    raise error
teamcity.diff_tools.EqualsAssertionError:  :: 1 != 0
20-07-01 00:46-ERROR- :: 1 != 0
Traceback (most recent call last):
  File "D:\PyCharm Community Edition 2020.1\plugins\python-ce\helpers\pycharm\teamcity\diff_tools.py", line 32, in _patched_equals
    old(self, first, second, msg)
  File "D:\python3.6.0\lib\unittest\case.py", line 821, in assertEqual
    assertion_func(first, second, msg=msg)
  File "D:\python3.6.0\lib\unittest\case.py", line 814, in _baseAssertEqual
    raise self.failureException(msg)
AssertionError: 1 != 0

During handling of the above exception, another exception occurred:

Traceback (most recent call last):
  File "C:\Users\legion\Desktop\API_AUTO\test_case\test_login.py", line 30, in test_api
    self.assertEqual(int(res.json()['ret']), item['expect'])
  File "D:\PyCharm Community Edition 2020.1\plugins\python-ce\helpers\pycharm\teamcity\diff_tools.py", line 38, in _patched_equals
    raise error
teamcity.diff_tools.EqualsAssertionError:  :: 1 != 0
